<?xml version="1.0"?>
<robot name="gypsy" xmlns:xacro="http://www.ros.org/wiki/xacro">
  <xacro:include filename="$(find gypsy_description)/urdf/gypsy.gazebo" />
  <!--xacro:include filename="$(find mybot_description)/urdf/materials.xacro" /-->
  <!--xacro:include filename="$(find mybot_description)/urdf/macros.xacro" /-->

  <link name="chassis">
    <visual>
      <geometry>
        <!--cylinder length="0.0508" radius="0.1524" /-->
	<mesh filename="package://gypsy_description/meshes/gypsy_frame.dae"/>
      </geometry>
      <material name="plastic">
        <color rgba="0 1 0 0" />
      </material>
    </visual>

    <collision>
      <geometry>
        <cylinder length="0.0508" radius="0.1524" />
      </geometry>
    </collision>

    <inertial>
      <mass value="10"/>
      <inertia
        ixx="1.0" ixy="0.0" ixz="0.0"
        iyy="1.0" iyz="0.0" izz="1.0"
      />
    </inertial>
  </link>

  <link name="right_wheel">
    <visual>
      <geometry>
        <cylinder length="0.01905" radius="0.061976" />
      </geometry>
      <material name="rubber">
        <color rgba="0 0 0 1" />
      </material>
    </visual>

    <collision>
      <geometry>
        <cylinder length="0.01905" radius="0.061976" />
      </geometry>
    </collision>

    <inertial>
      <mass value="1"/>
      <inertia
        ixx="1.0" ixy="0.0" ixz="0.0"
        iyy="1.0" iyz="0.0" izz="1.0"
      />
    </inertial>
  </link>

  <joint name="right_wheel_joint" type="continuous">
    <parent link="chassis" />
    <child link="right_wheel" />
    <origin xyz="0 -0.168402 0" rpy="1.57075 0 0" />
    <axis xyz="0 0 1" />
    <limit effort="100" velocity="100"/>
    <dynamics damping="0.0" friction="0.0"/>
  </joint>

  <link name="left_wheel">
    <visual>
      <geometry>
        <cylinder length="0.01905" radius="0.061976" />
      </geometry>
      <material name="rubber" />
    </visual>

    <collision>
      <geometry>
        <cylinder length="0.01905" radius="0.061976" />
      </geometry>
    </collision>

    <inertial>
      <mass value="1"/>
      <inertia
        ixx="1.0" ixy="0.0" ixz="0.0"
        iyy="1.0" iyz="0.0" izz="1.0"
      />
    </inertial>
  </link>

  <joint name="left_wheel_joint" type="continuous">
    <parent link="chassis" />
    <child link="left_wheel" />
    <origin xyz="0 0.168402 0" rpy="1.57075 0 0" />
    <axis xyz="0 0 1" />
    <limit effort="100" velocity="100"/>
    <dynamics damping="0.0" friction="0.0"/>
  </joint>
</robot>
